<mujoco model="ur5 scene">

  <include file="ur5.xml"/>
  <include file="2f85.xml"/>

  <size memory="2M"/>
  <option integrator="implicitfast"  timestep="0.0005" noslip_iterations="50" viscosity="0.00" gravity="0.0 0.0 -9.81">
    <flag multiccd="enable"/>
  </option>

  <statistic center="0.3 0 0.4" extent="0.8"/>

  <visual>
    <headlight diffuse="0.6 0.6 0.6"  ambient="0.1 0.1 0.1" specular="0 0 0"/>
    <rgba haze="0.15 0.25 0.35 1"/>
    <global azimuth="120" elevation="-20"/>
  </visual>

  <asset>
    <texture type="skybox" builtin="gradient" rgb1="0.3 0.5 0.7" 
             rgb2="0 0 0" width="512" height="3072"/>

    <texture type="2d" name="groundplane" builtin="checker" mark="edge" rgb1="0.2 0.3 0.4"
             rgb2="0.1 0.2 0.3" markrgb="0.8 0.8 0.8" width="300" height="300"/>

    <material name="groundplane" texture="groundplane" texuniform="true" texrepeat="5 5"
              reflectance="0.2"/>
  </asset>

  <default class="obj_sites">
      <site type='cylinder' size='0.003 0.006' group="3"/>
      <default class="site_top"> 
        <geom rgba='1 0 0 0' type='cylinder' size='0.003 0.003' conaffinity="0" contype="0"  group="1" mass="0.00001"/>
        <site rgba='1 0 0 1' zaxis="0 0 1"/>
      </default>
      <default class="site_bottom"> 
        <geom rgba='0 1 0 0.3' type='cylinder' size='0.003 0.003' conaffinity="0" contype="0"  group="1" mass="0.00001"/>
        <site rgba='0 1 0 0.3' zaxis="0 0 -1" />
      </default>
      <default class="site_front"> 
        <geom rgba='1 1 0 0.3' type='cylinder' size='0.003 0.003' conaffinity="0" contype="0"  group="1" mass="0.00001"/>
        <site rgba='1 1 0 0.3' zaxis="0 1 0" />
      </default>
      <default class="site_back"> 
        <geom rgba='0 1 1 0.3' type='cylinder' size='0.003 0.003' conaffinity="0" contype="0"  group="1" mass="0.00001"/>
        <site rgba='0 1 1 0.3' zaxis="0 -1 0"/>
      </default>
      <default class="site_left"> 
        <geom rgba='1 0 1 0.3' type='cylinder' size='0.003 0.006' zaxis="-1 0 0" conaffinity="0" contype="0"  group="1" mass="0.00001"/>
        <site rgba='1 0 1 0.3' zaxis="-1 0 0"/>
      </default>
      <default class="site_right"> 
        <geom rgba='0 0 1 0.3' type='cylinder' size='0.003 0.003' conaffinity="0" contype="0"  group="1" mass="0.00001"/>
        <site rgba='0 0 1 0.3' zaxis="1 0 0" />
      </default>
       
    </default>

  <worldbody>
    <light pos="0 0 1.5" dir="0 0 -1" directional="true"/>
    <geom name="floor" size="2.0 1.5 0.05" type="plane" material="groundplane"/>
    <geom name="table" type="box" size="1.0 0.5 0.015" pos="0 0 0.36" euler="0.00 0 0"/>
    <geom name="desk" type="box" size="0.1 0.1 0.1" pos="0 0 0.41" material="metal"/>

    <geom class='visual' name="region" type="box" size="0.05 0.05 0.015" pos="0.5 -0.1 0.37" rgba="0.3 0.7 0.4 0.5" euler="0 0 3."/>

    <body name="cube1" pos="0.4 0.3 1.75" euler="0 0 1.05">
      <inertial mass="0.05" pos="0 0 0" quat="1 0 0 0" diaginertia="0.0000260285 0.0000225381 0.0000152708"/>
      <joint type="free" pos="0 0 0"/>
      <geom type="box" size="0.03 0.025 0.05" pos="0 0 0" rgba="1 0 0 1" condim="6" 
            solimp="0.9 0.95 0.001 0.5 2" solref="0.0001 2" friction="4.95 0.05 0.001" contype="1" conaffinity="1"/>
    </body>

    <body name="cable0" pos="0.4 0.3 1.85" gravcomp="0.0">
      <inertial pos="0.0 0 0.03" mass="0.73" diaginertia="0.0025 0.001 0.0017"/>
      <joint type="free"/>
      <body name="B_first" pos="0 0 0" gravcomp="1.0">
        <geom name="G0" size="0.003 0.00520833" pos="0.00520833 0 0" quat="0.707107 0 -0.707107 0" type="capsule" contype="1" rgba="0.8 0.2 0.1 1"/>
        <site name="S_first" pos="0 0 0" group="3"/>
        <!-- feature point -->
        <site name="marker0" pos="0 0 0" type="sphere" size="0.0045" rgba="0 1 0 0.5"/>

        <body name="B_1" pos="0.0104167 0 0" gravcomp="1.0">
          <joint name="J_1" pos="0 0 0" type="ball" group="3" stiffness="0.00" damping="0.03"/>
          <geom name="G1" size="0.003 0.00520833" pos="0.00520833 0 0" quat="0.707107 0 -0.707107 0" type="capsule" contype="1" rgba="0.8 0.2 0.1 1"/>
          <body name="B_2" pos="0.0104167 0 0" gravcomp="1.0">
            <joint name="J_2" pos="0 0 0" type="ball" group="3" stiffness="0.03" damping="0.03"/>
            <geom name="G2" size="0.003 0.00520833" pos="0.00520833 0 0" quat="0.707107 0 -0.707107 0" type="capsule" contype="1" rgba="0.8 0.2 0.1 1"/>
            <!-- feature point -->
            <site name="marker2" pos="0 0 0" type="sphere" size="0.0045" rgba="0 1 0 0.5"/>
            <body name="B_3" pos="0.0104167 0 0" gravcomp="1.0">
              <joint name="J_3" pos="0 0 0" type="ball" group="3" stiffness="0.00" damping="0.03"/>
              <geom name="G3" size="0.003 0.00520833" pos="0.00520833 0 0" quat="0.707107 0 -0.707107 0" type="capsule" contype="1" rgba="0.8 0.2 0.1 1"/>
              <body name="B_4" pos="0.0104167 0 0" gravcomp="1.0">
                <joint name="J_4" pos="0 0 0" type="ball" group="3" damping="0.03"/>
                <geom name="G4" size="0.003 0.00520833" pos="0.00520833 0 0" quat="0.707107 0 -0.707107 0" type="capsule" contype="1" rgba="0.8 0.2 0.1 1"/>
                <!-- feature point -->
                <site name="marker4" pos="0 0 0" type="sphere" size="0.0045" rgba="0 1 0 0.5"/>
                <body name="B_5" pos="0.0104167 0 0" gravcomp="1.0">
                  <joint name="J_5" pos="0 0 0" type="ball" group="3" damping="0.03"/>
                  <geom name="G5" size="0.003 0.00520833" pos="0.00520833 0 0" quat="0.707107 0 -0.707107 0" type="capsule" contype="1" rgba="0.8 0.2 0.1 1"/>
                  <body name="B_6" pos="0.0104167 0 0" gravcomp="1.0">
                    <joint name="J_6" pos="0 0 0" type="ball" group="3" damping="0.03"/>
                    <geom name="G6" size="0.003 0.00520833" pos="0.00520833 0 0" quat="0.707107 0 -0.707107 0" type="capsule" contype="1" rgba="0.8 0.2 0.1 1"/>
                    <!-- feature point -->
                    <site name="marker6" pos="0 0 0" type="sphere" size="0.0045" rgba="0 1 0 0.5"/>
                    <body name="B_7" pos="0.0104167 0 0" gravcomp="1.0">
                      <joint name="J_7" pos="0 0 0" type="ball" group="3" damping="0.03"/>
                      <geom name="G7" size="0.003 0.00520834" pos="0.00520834 0 0" quat="0.707107 0 -0.707107 0" type="capsule" contype="1" rgba="0.8 0.2 0.1 1"/>
                      <body name="B_8" pos="0.0104167 0 0" gravcomp="1.0">
                        <joint name="J_8" pos="0 0 0" type="ball" group="3" damping="0.03"/>
                        <geom name="G8" size="0.003 0.00520833" pos="0.00520833 0 0" quat="0.707107 0 -0.707107 0" type="capsule" contype="1" rgba="0.8 0.2 0.1 1"/>
                        <!-- feature point -->
                        <site name="marker8" pos="0 0 0" type="sphere" size="0.0045" rgba="0 1 0 0.5"/>
                        <body name="B_9" pos="0.0104167 0 0" gravcomp="1.0">
                          <joint name="J_9" pos="0 0 0" type="ball" group="3" damping="0.03"/>
                          <geom name="G9" size="0.003 0.00520833" pos="0.00520833 0 0" quat="0.707107 0 -0.707107 0" type="capsule" contype="1" rgba="0.8 0.2 0.1 1"/>
                          <body name="B_10" pos="0.0104167 0 0" gravcomp="1.0">
                            <joint name="J_10" pos="0 0 0" type="ball" group="3" damping="0.03"/>
                            <geom name="G10" size="0.003 0.00520834" pos="0.00520834 0 0" quat="0.707107 0 -0.707107 0" type="capsule" contype="1" rgba="0.8 0.2 0.1 1"/>
                            <!-- feature point -->
                            <site name="marker10" pos="0 0 0" type="sphere" size="0.0045" rgba="0 1 0 0.5"/>
                            <body name="B_11" pos="0.0104167 0 0" gravcomp="1.0">
                              <joint name="J_11" pos="0 0 0" type="ball" group="3" damping="0.03"/>
                              <geom name="G11" size="0.003 0.00520833" pos="0.00520833 0 0" quat="0.707107 0 -0.707107 0" type="capsule" contype="1" rgba="0.8 0.2 0.1 1"/>
                              <body name="B_12" pos="0.0104167 0 0" gravcomp="1.0">
                                <joint name="J_12" pos="0 0 0" type="ball" group="3" damping="0.03"/>
                                <geom name="G12" size="0.003 0.00520834" pos="0.00520834 0 0" quat="0.707107 0 -0.707107 0" type="capsule" contype="1" rgba="0.8 0.2 0.1 1"/>
                                <!-- feature point -->
                                <site name="marker12" pos="0 0 0" type="sphere" size="0.0045" rgba="0 1 0 0.5"/>
                                <body name="B_13" pos="0.0104167 0 0" gravcomp="1.0">
                                  <joint name="J_13" pos="0 0 0" type="ball" group="3" damping="0.03"/>
                                  <geom name="G13" size="0.003 0.00520833" pos="0.00520833 0 0" quat="0.707107 0 -0.707107 0" type="capsule" contype="1" rgba="0.8 0.2 0.1 1"/>
                                  <body name="B_14" pos="0.0104167 0 0" gravcomp="1.0">
                                    <joint name="J_14" pos="0 0 0" type="ball" group="3" damping="0.03"/>
                                    <geom name="G14" size="0.003 0.00520834" pos="0.00520834 0 0" quat="0.707107 0 -0.707107 0" type="capsule" contype="1" rgba="0.8 0.2 0.1 1"/>
                                    <!-- feature point -->
                                    <site name="marker14" pos="0 0 0" type="sphere" size="0.0045" rgba="0 1 0 0.5"/>
                                    <body name="B_15" pos="0.0104167 0 0" gravcomp="1.0">
                                      <joint name="J_15" pos="0 0 0" type="ball" group="3" damping="0.03"/>
                                      <geom name="G15" size="0.003 0.00520834" pos="0.00520834 0 0" quat="0.707107 0 -0.707107 0" type="capsule" contype="1" rgba="0.8 0.2 0.1 1"/>
                                      <body name="B_16" pos="0.0104167 0 0" gravcomp="1.0">
                                        <joint name="J_16" pos="0 0 0" type="ball" group="3" damping="0.03"/>
                                        <geom name="G16" size="0.003 0.00520833" pos="0.00520833 0 0" quat="0.707107 0 -0.707107 0" type="capsule" contype="1" rgba="0.8 0.2 0.1 1"/>
                                        <!-- feature point -->
                                        <site name="marker16" pos="0 0 0" type="sphere" size="0.0045" rgba="0 1 0 0.5"/>
                                        <body name="B_17" pos="0.0104167 0 0" gravcomp="1.0">
                                          <joint name="J_17" pos="0 0 0" type="ball" group="3" damping="0.03"/>
                                          <geom name="G17" size="0.003 0.00520834" pos="0.00520834 0 0" quat="0.707107 0 -0.707107 0" type="capsule" contype="1" rgba="0.8 0.2 0.1 1"/>
                                          <body name="B_18" pos="0.0104167 0 0" gravcomp="1.0">
                                            <joint name="J_18" pos="0 0 0" type="ball" group="3" damping="0.03"/>
                                            <geom name="G18" size="0.003 0.00520834" pos="0.00520834 0 0" quat="0.707107 0 -0.707107 0" type="capsule" contype="1" rgba="0.8 0.2 0.1 1"/>
                                            <!-- feature point -->
                                            <site name="marker18" pos="0 0 0" type="sphere" size="0.0045" rgba="0 1 0 0.5"/>
                                            <body name="B_19" pos="0.0104167 0 0" gravcomp="1.0">
                                              <joint name="J_19" pos="0 0 0" type="ball" group="3" damping="0.03"/>
                                              <geom name="G19" size="0.003 0.00520833" pos="0.00520833 0 0" quat="0.707107 0 -0.707107 0" type="capsule" contype="1" rgba="0.8 0.2 0.1 1"/>
                                              <body name="B_20" pos="0.0104167 0 0" gravcomp="1.0">
                                                <joint name="J_20" pos="0 0 0" type="ball" group="3" damping="0.03"/>
                                                <geom name="G20" size="0.003 0.00520834" pos="0.00520834 0 0" quat="0.707107 0 -0.707107 0" type="capsule" contype="1" rgba="0.8 0.2 0.1 1"/>
                                                <!-- feature point -->
                                                <site name="marker20" pos="0 0 0" type="sphere" size="0.0045" rgba="0 1 0 0.5"/>
                                                <body name="B_21" pos="0.0104167 0 0" gravcomp="1.0">
                                                  <joint name="J_21" pos="0 0 0" type="ball" group="3" damping="0.03"/>
                                                  <geom name="G21" size="0.003 0.00520834" pos="0.00520834 0 0" quat="0.707107 0 -0.707107 0" type="capsule" contype="1" rgba="0.8 0.2 0.1 1"/>
                                                  <body name="B_22" pos="0.0104167 0 0" gravcomp="1.0">
                                                    <joint name="J_22" pos="0 0 0" type="ball" group="3" damping="0.03"/>
                                                    <geom name="G22" size="0.003 0.00520833" pos="0.00520833 0 0" quat="0.707107 0 -0.707107 0" type="capsule" contype="1" rgba="0.8 0.2 0.1 1"/>
                                                    <body name="B_last" pos="0.0104167 0 0" gravcomp="1.0">
                                                      <joint name="J_last" pos="0 0 0" type="ball" group="3" damping="0.03"/>
                                                      <geom name="G23" size="0.003 0.00520834" pos="0.00520834 0 0" quat="0.707107 0 -0.707107 0" type="capsule" contype="1" rgba="0.8 0.2 0.1 1"/>
                                                      <!-- feature point -->
                                                      <site name="marker23" pos="0.00 0 0" type="sphere" size="0.0045" rgba="0 1 0 0.5"/>
                                                      <site name="S_last" pos="0.0104167 0 0" group="3"/>
                                                    </body>
                                                  </body>
                                                </body>
                                              </body>
                                            </body>
                                          </body>
                                        </body>
                                      </body>
                                    </body>
                                  </body>
                                </body>
                              </body>
                            </body>
                          </body>
                        </body>
                      </body>
                    </body>
                  </body>
                </body>
              </body>
            </body>
          </body>
        </body>
      </body>
    </body>

  </worldbody>

</mujoco>