<mujoco model="ur5">
    <compiler angle="radian" meshdir="visual" />
    <!-- <size njmax="500" nconmax="100" /> -->
    <asset>
        <mesh name="base" file="base.stl" />
        <mesh name="shoulder" file="shoulder.stl" />
        <mesh name="upperarm" file="upperarm.stl" />
        <mesh name="forearm" file="forearm.stl" />
        <mesh name="wrist1" file="wrist1.stl" />
        <mesh name="wrist2" file="wrist2.stl" />
        <mesh name="wrist3" file="wrist3.stl" />
    </asset>
    <worldbody>
        
        <body name="base_link" pos="0 0 0.5">
            <geom type="mesh" contype="0" conaffinity="0" group="1" rgba="0.7 0.7 0.7 1" mesh="base" />
            <geom type="mesh" rgba="0.7 0.7 0.7 1" mesh="base" />
            <body name="shoulder_link" pos="0 0 0.089159">
                <inertial pos="0 0 0" mass="3.7" diaginertia="0.0102675 0.0102675 0.00666" />
                <joint name="shoulder_pan_joint" pos="0 0 0" axis="0 0 1" limited="true" range="-3.14159 3.14159" damping="0.1"/>
                <geom type="mesh" contype="0" conaffinity="0" group="1" rgba="0.7 0.7 0.7 1" mesh="shoulder" />
                <geom type="mesh" rgba="0.7 0.7 0.7 1" mesh="shoulder" />

                <body name="upper_arm_link" pos="0 0.13585 0" quat="0.707107 0 0.707107 0">
                    <inertial pos="0 0 0.28" mass="8.393" diaginertia="0.226891 0.226891 0.0151074" />
                    <joint name="shoulder_lift_joint" pos="0 0 0" axis="0 1 0" limited="true" range="-3.14159 3.14159" damping="0.1"/>
                    <geom type="mesh" contype="0" conaffinity="0" group="1" rgba="0.7 0.7 0.7 1" mesh="upperarm" />
                    <geom type="mesh" mesh="upperarm" />

                    <body name="forearm_link" pos="0 -0.1197 0.425">
                        <inertial pos="0 0 0.25" mass="2.275" diaginertia="0.0312168 0.0312168 0.004095" />
                        <joint name="elbow_joint" pos="0 0 0" axis="0 1 0" limited="true" range="-3.14159 3.14159" damping="0.1"/>
                        <geom type="mesh" contype="0" conaffinity="0" group="1" rgba="0.7 0.7 0.7 1" mesh="forearm" />
                        <geom type="mesh" mesh="forearm" />

                        <body name="wrist_1_link" pos="0 0 0.39225" quat="0.707107 0 0.707107 0">
                            <inertial pos="0 0.093 0" mass="1.219" diaginertia="0.0025599 0.0025599 0.0021942" />
                            <joint name="wrist_1_joint" pos="0 0 0" axis="0 1 0" limited="true" range="-3.14159 3.14159" damping="0.1"/>
                            <geom type="mesh" contype="0" conaffinity="0" group="1" rgba="0.7 0.7 0.7 1" mesh="wrist1" />
                            <geom type="mesh" rgba="0.7 0.7 0.7 1" mesh="wrist1" />
                            
                            <body name="wrist_2_link" pos="0 0.093 0">
                                <inertial pos="0 0 0.09465" mass="1.219" diaginertia="0.0025599 0.0025599 0.0021942" />
                                <joint name="wrist_2_joint" pos="0 0 0" axis="0 0 1" limited="true" range="-3.14159 3.14159" damping="0.1"/>
                                <geom type="mesh" contype="0" conaffinity="0" group="1" rgba="0.7 0.7 0.7 1" mesh="wrist2" />
                                <geom type="mesh" rgba="0.7 0.7 0.7 1" mesh="wrist2" />

                                <body name="wrist_3_link" pos="0 0 0.09465">
                                    <inertial pos="0 0.06505 0" quat="1.73123e-12 0.707107 -0.707107 1.73123e-12" 
                                            mass="0.1879" diaginertia="0.000132117 8.46959e-05 8.46959e-05" />
                                    <joint name="wrist_3_joint" pos="0 0 0" axis="0 1 0" limited="true" range="-3.14159 3.14159" damping="0.1"/>
                                    <geom type="mesh" contype="0" conaffinity="0" group="1" mesh="wrist3" />
                                    <geom type="mesh" mesh="wrist3" rgba="1 0 0 1"/>
                                    <site name="arm_ee" pos="0 0 0" rgba="1 0 0 1" size="0.01" type="sphere"/>

                                    <!-- Gripper Parts -->
                                    <body name="gripper_base" pos="0.0 0.08 0.0" quat="0.7071068 -0.7071068 0 0">
                                        <inertial mass="0.777441" pos="0 -2.70394e-05 0.0354675" quat="1 -0.00152849 0 0"
                                        diaginertia="0.000260285 0.000225381 0.000152708"/>
                                        <geom class="visual" mesh="g_base" material="black"/>
                                        <geom class="collision" mesh="g_base"/>
                                        <site name="pinch" pos="0 0 0.145" type="sphere" rgba="0.9 0.3 0.3 1" size="0.01"/>

                                        <!-- Right-hand side 4-bar linkage -->
                                        <body name="right_driver" pos="0 0.0306011 0.054904">
                                        <inertial mass="0.00899563" pos="2.96931e-12 0.0177547 0.00107314" quat="0.681301 0.732003 0 0"
                                            diaginertia="1.72352e-06 1.60906e-06 3.22006e-07"/>
                                        <joint name="right_driver_joint" class="driver"/>
                                        <geom class="visual" mesh="driver" material="gray"/>
                                        <geom class="collision" mesh="driver"/>
                                        <body name="right_coupler" pos="0 0.0315 -0.0041">
                                            <inertial mass="0.0140974" pos="0 0.00301209 0.0232175" quat="0.705636 -0.0455904 0.0455904 0.705636"
                                            diaginertia="4.16206e-06 3.52216e-06 8.88131e-07"/>
                                            <joint name="right_coupler_joint" class="coupler"/>
                                            <geom class="visual" mesh="coupler" material="black"/>
                                            <geom class="collision" mesh="coupler"/>
                                        </body>
                                        </body>
                                        <body name="right_spring_link" pos="0 0.0132 0.0609">
                                        <inertial mass="0.0221642" pos="-8.65005e-09 0.0181624 0.0212658" quat="0.663403 -0.244737 0.244737 0.663403"
                                            diaginertia="8.96853e-06 6.71733e-06 2.63931e-06"/>
                                        <joint name="right_spring_link_joint" class="spring_link"/>
                                        <geom class="visual" mesh="spring_link" material="black"/>
                                        <geom class="collision" mesh="spring_link"/>
                                        <body name="right_follower" pos="0 0.055 0.0375">
                                            <inertial mass="0.0125222" pos="0 -0.011046 0.0124786" quat="1 0.1664 0 0"
                                            diaginertia="2.67415e-06 2.4559e-06 6.02031e-07"/>
                                            <joint name="right_follower_joint" class="follower"/>
                                            <geom class="visual" mesh="follower" material="black"/>
                                            <geom class="collision" mesh="follower"/>
                                            <body name="right_pad" pos="0 -0.0189 0.01352">
                                            <geom class="pad_box1" name="right_pad1"/>
                                            <geom class="pad_box2" name="right_pad2"/>
                                            <inertial mass="0.0035" pos="0 -0.0025 0.0185" quat="0.707107 0 0 0.707107"
                                                diaginertia="4.73958e-07 3.64583e-07 1.23958e-07"/>
                                            <geom class="visual" mesh="pad"/>
                                            <body name="right_silicone_pad">
                                                <geom class="visual" mesh="silicone_pad" material="black"/>
                                            </body>
                                            </body>
                                        </body>
                                        </body>
                                        <!-- Left-hand side 4-bar linkage -->
                                        <body name="left_driver" pos="0 -0.0306011 0.054904" quat="0 0 0 1">
                                        <inertial mass="0.00899563" pos="0 0.0177547 0.00107314" quat="0.681301 0.732003 0 0"
                                            diaginertia="1.72352e-06 1.60906e-06 3.22006e-07"/>
                                        <joint name="left_driver_joint" class="driver"/>
                                        <geom class="visual" mesh="driver" material="gray"/>
                                        <geom class="collision" mesh="driver"/>
                                        <body name="left_coupler" pos="0 0.0315 -0.0041">
                                            <inertial mass="0.0140974" pos="0 0.00301209 0.0232175" quat="0.705636 -0.0455904 0.0455904 0.705636"
                                            diaginertia="4.16206e-06 3.52216e-06 8.88131e-07"/>
                                            <joint name="left_coupler_joint" class="coupler"/>
                                            <geom class="visual" mesh="coupler" material="black"/>
                                            <geom class="collision" mesh="coupler"/>
                                        </body>
                                        </body>
                                        <body name="left_spring_link" pos="0 -0.0132 0.0609" quat="0 0 0 1">
                                        <inertial mass="0.0221642" pos="-8.65005e-09 0.0181624 0.0212658" quat="0.663403 -0.244737 0.244737 0.663403"
                                            diaginertia="8.96853e-06 6.71733e-06 2.63931e-06"/>
                                        <joint name="left_spring_link_joint" class="spring_link"/>
                                        <geom class="visual" mesh="spring_link" material="black"/>
                                        <geom class="collision" mesh="spring_link"/>
                                        <body name="left_follower" pos="0 0.055 0.0375">
                                            <inertial mass="0.0125222" pos="0 -0.011046 0.0124786" quat="1 0.1664 0 0"
                                            diaginertia="2.67415e-06 2.4559e-06 6.02031e-07"/>
                                            <joint name="left_follower_joint" class="follower"/>
                                            <geom class="visual" mesh="follower" material="black"/>
                                            <geom class="collision" mesh="follower"/>
                                            <body name="left_pad" pos="0 -0.0189 0.01352">
                                            <geom class="pad_box1" name="left_pad1"/>
                                            <geom class="pad_box2" name="left_pad2"/>
                                            <inertial mass="0.0035" pos="0 -0.0025 0.0185" quat="1 0 0 1"
                                                diaginertia="4.73958e-07 3.64583e-07 1.23958e-07"/>
                                            <geom class="visual" mesh="pad"/>
                                            <body name="left_silicone_pad">
                                                <geom class="visual" mesh="silicone_pad" material="black"/>
                                            </body>
                                            </body>
                                        </body>
                                        </body>
                                    </body>
                                </body>
                            </body>
                        </body>
                    </body>
                </body>
            </body>
        </body>
    </worldbody>
    <actuator>
        <position name='motor1' ctrllimited="true" ctrlrange="-3.14159 3.14159" joint='shoulder_pan_joint' kp="800"/>
        <position name='motor2' ctrllimited="true" ctrlrange="-3.14159 3.14159" joint='shoulder_lift_joint' kp="800"/>
        <position name='motor3' ctrllimited="true" ctrlrange="-3.14159 3.14159" joint='elbow_joint' kp="800"/>
        <position name='motor4' ctrllimited="true" ctrlrange="-3.14159 3.14159" joint='wrist_1_joint' kp="350"/>
        <position name='motor5' ctrllimited="true" ctrlrange="-3.14159 3.14159" joint='wrist_2_joint' kp="250"/>
        <position name='motor6' ctrllimited="true" ctrlrange="-3.14159 3.14159" joint='wrist_3_joint' kp="250"/>

        <velocity name='vmotor1' ctrllimited="true" ctrlrange="-100 100" joint='shoulder_pan_joint' kv="85"/>
        <velocity name='vmotor2' ctrllimited="true" ctrlrange="-100 100" joint='shoulder_lift_joint' kv="85"/>
        <velocity name='vmotor3' ctrllimited="true" ctrlrange="-100 100" joint='elbow_joint' kv="75"/>
        <velocity name='vmotor4' ctrllimited="true" ctrlrange="-100 100" joint='wrist_1_joint' kv="20"/>
        <velocity name='vmotor5' ctrllimited="true" ctrlrange="-100 100" joint='wrist_2_joint' kv="10"/>
        <velocity name='vmotor6' ctrllimited="true" ctrlrange="-100 100" joint='wrist_3_joint' kv="10"/>

        <general class="2f85" name="fingers_actuator" tendon="split" forcerange="-5 5" ctrlrange="0 255"
      gainprm="0.3137255 0 0" biasprm="0 -100 -10"/>
    </actuator>

    <sensor>
        <jointpos name='joint1' joint='shoulder_pan_joint'/>
        <jointpos name='joint2' joint='shoulder_lift_joint'/>
        <jointpos name='joint3' joint='elbow_joint'/>
        <jointpos name='joint4' joint='wrist_1_joint'/>
        <jointpos name='joint5' joint='wrist_2_joint'/>
        <jointpos name='joint6' joint='wrist_3_joint'/>
    </sensor>
</mujoco>