<mujoco model="ur5">
    <compiler angle="radian" meshdir="visual" />
    <size njmax="500" nconmax="100" />
    <asset>
        <mesh name="base" file="base.stl" />
        <mesh name="shoulder" file="shoulder.stl" />
        <mesh name="upperarm" file="upperarm.stl" />
        <mesh name="forearm" file="forearm.stl" />
        <mesh name="wrist1" file="wrist1.stl" />
        <mesh name="wrist2" file="wrist2.stl" />
        <mesh name="wrist3" file="wrist3.stl" />
    </asset>
    <worldbody>
        <body name="base_link" pos="0 0 0.5">
            <geom type="mesh" contype="0" conaffinity="0" group="1" rgba="0.7 0.7 0.7 1" mesh="base" />
            <geom type="mesh" rgba="0.7 0.7 0.7 1" mesh="base" />
            <body name="shoulder_link" pos="0 0 0.089159">
                <inertial pos="0 0 0" mass="3.7" diaginertia="0.0102675 0.0102675 0.00666" />
                <joint name="shoulder_pan_joint" pos="0 0 0" axis="0 0 1" limited="true" range="-3.14159 3.14159" damping="1.1"/>
                <geom type="mesh" contype="0" conaffinity="0" group="1" rgba="0.7 0.7 0.7 1" mesh="shoulder" />
                <geom type="mesh" rgba="0.7 0.7 0.7 1" mesh="shoulder" />

                <body name="upper_arm_link" pos="0 0.13585 0" quat="0.707107 0 0.707107 0">
                    <inertial pos="0 0 0.28" mass="8.393" diaginertia="0.226891 0.226891 0.0151074" />
                    <joint name="shoulder_lift_joint" pos="0 0 0" axis="0 1 0" limited="true" range="-3.14159 3.14159" damping="1.1"/>
                    <geom type="mesh" contype="0" conaffinity="0" group="1" rgba="0.7 0.7 0.7 1" mesh="upperarm" />
                    <geom type="mesh" mesh="upperarm" />

                    <body name="forearm_link" pos="0 -0.1197 0.425">
                        <inertial pos="0 0 0.25" mass="2.275" diaginertia="0.0312168 0.0312168 0.004095" />
                        <joint name="elbow_joint" pos="0 0 0" axis="0 1 0" limited="true" range="-3.14159 3.14159" damping="1.1"/>
                        <geom type="mesh" contype="0" conaffinity="0" group="1" rgba="0.7 0.7 0.7 1" mesh="forearm" />
                        <geom type="mesh" mesh="forearm" />

                        <body name="wrist_1_link" pos="0 0 0.39225" quat="0.707107 0 0.707107 0">
                            <inertial pos="0 0.093 0" mass="1.219" diaginertia="0.0025599 0.0025599 0.0021942" />
                            <joint name="wrist_1_joint" pos="0 0 0" axis="0 1 0" limited="true" range="-3.14159 3.14159" damping="1.1"/>
                            <geom type="mesh" contype="0" conaffinity="0" group="1" rgba="0.7 0.7 0.7 1" mesh="wrist1" />
                            <geom type="mesh" rgba="0.7 0.7 0.7 1" mesh="wrist1" />
                            
                            <body name="wrist_2_link" pos="0 0.093 0">
                                <inertial pos="0 0 0.09465" mass="1.219" diaginertia="0.0025599 0.0025599 0.0021942" />
                                <joint name="wrist_2_joint" pos="0 0 0" axis="0 0 1" limited="true" range="-3.14159 3.14159" damping="1.1"/>
                                <geom type="mesh" contype="0" conaffinity="0" group="1" rgba="0.7 0.7 0.7 1" mesh="wrist2" />
                                <geom type="mesh" rgba="0.7 0.7 0.7 1" mesh="wrist2" />

                                <body name="wrist_3_link" pos="0 0 0.09465">
                                    <inertial pos="0 0.06505 0" quat="1.73123e-12 0.707107 -0.707107 1.73123e-12" 
                                              mass="0.1879" diaginertia="0.000132117 8.46959e-05 8.46959e-05" />
                                    <joint name="wrist_3_joint" pos="0 0 0" axis="0 1 0" limited="true" range="-3.14159 3.14159" damping="1.1"/>
                                    <geom type="mesh" contype="0" conaffinity="0" group="1" mesh="wrist3" />
                                    <geom type="mesh" mesh="wrist3" rgba="1 0 0 1"/>
                                    <site name="arm_ee" pos="0 0 0" rgba="1 0 0 1" size="0.01" type="sphere"/>

                                    <!-- Simple Gripper Parts -->
                                    <body name="gripper_base" pos="0.0 0.08 0.0" quat="0.7071068 -0.7071068 0 0">
                                        <inertial mass="0.777441" pos="0 -2.70394e-05 0.0354675" quat="1 -0.00152849 0 0" diaginertia="0.000260285 0.000225381 0.000152708"/>
                                        <geom class="visual" mesh="g_base" material="black"/>
                                        <geom class="visual" type="box" size="0.01 0.06 0.01" pos="0 0 0.105" material="black"/>
                                        <site name="pinch" pos="0 0 0.145" type="sphere" rgba="0.9 0.3 0.3 1" size="0.01"/>

                                        <!-- Right-Finger -->
                                        <body name="right_finger" pos="0 0.055 0.13">
                                            <inertial mass="0.015" pos="0 0 0" diaginertia="2.375e-6 2.375e-6 7.5e-7"/>
                                            <joint name="finger_joint_r" class="finger"/> 
                                            <geom type="box" size="0.012 0.005 0.025" pos="0 0 0" rgba="1 0.5 0 1"  condim="6"
                                                solref="0.0001 2" friction="4 2 2.0" conaffinity="1" contype="1"
                                                solimp="0.9 0.95 0.001 0.5 2"/>
                                        </body>

                                        <!-- Left-Finger -->
                                        <body name="left_finger" pos="0 -0.055 0.13">
                                            <inertial mass="0.015" pos="0 0 0" diaginertia="2.375e-6 2.375e-6 7.5e-7"/>
                                            <joint name="finger_joint_l" class="finger"/> 
                                            <geom type="box" size="0.012 0.005 0.025" pos="0 0 0" rgba="1 0.5 0 1"  condim="6"
                                                solref="0.0001 2" friction="4 2.0 2.0" conaffinity="1" contype="1"
                                                solimp="0.9 0.95 0.001 0.5 2"/>
                                        </body>
                                    </body>
                                </body>
                            </body>
                        </body>
                    </body>
                </body>
            </body>
        </body>
    </worldbody>
    
    <contact>
        <exclude body1="gripper_base" body2="left_finger"/>
        <exclude body1="gripper_base" body2="right_finger"/>
    </contact>


    <actuator>
        <position name='motor1' ctrllimited="true" ctrlrange="-3.14159 3.14159" joint='shoulder_pan_joint' kp="750"/>
        <position name='motor2' ctrllimited="true" ctrlrange="-3.14159 3.14159" joint='shoulder_lift_joint' kp="750"/>
        <position name='motor3' ctrllimited="true" ctrlrange="-3.14159 3.14159" joint='elbow_joint' kp="750"/>
        <position name='motor4' ctrllimited="true" ctrlrange="-3.14159 3.14159" joint='wrist_1_joint' kp="750"/>
        <position name='motor5' ctrllimited="true" ctrlrange="-3.14159 3.14159" joint='wrist_2_joint' kp="600"/>
        <position name='motor6' ctrllimited="true" ctrlrange="-3.14159 3.14159" joint='wrist_3_joint' kp="600"/>

        <velocity name='vmotor1' ctrllimited="true" ctrlrange="-10 10" joint='shoulder_pan_joint' kv="35"/>
        <velocity name='vmotor2' ctrllimited="true" ctrlrange="-10 10" joint='shoulder_lift_joint' kv="35"/>
        <velocity name='vmotor3' ctrllimited="true" ctrlrange="-10 10" joint='elbow_joint' kv="35"/>
        <velocity name='vmotor4' ctrllimited="true" ctrlrange="-10 10" joint='wrist_1_joint' kv="25"/>
        <velocity name='vmotor5' ctrllimited="true" ctrlrange="-10 10" joint='wrist_2_joint' kv="25"/>
        <velocity name='vmotor6' ctrllimited="true" ctrlrange="-10 10" joint='wrist_3_joint' kv="25"/>

        <position name="finger_left"  joint="finger_joint_l" ctrllimited="true" ctrlrange="-0.045 0.045" kp="800" forcelimited="true" forcerange="-20 20"/>
        <position name="finger_right" joint="finger_joint_r" ctrllimited="true" ctrlrange="-0.045 0.045" kp="800" forcelimited="true" forcerange="-20 20"/>

        <velocity name="vfinger_left"  joint="finger_joint_l" ctrlrange="-1.5 1.5" kv="20"/>
        <velocity name="vfinger_right" joint="finger_joint_r" ctrlrange="-1.5 1.5" kv="20"/>
        
    </actuator>

    <sensor>
        <jointpos name='joint1' joint='shoulder_pan_joint'/>
        <jointpos name='joint2' joint='shoulder_lift_joint'/>
        <jointpos name='joint3' joint='elbow_joint'/>
        <jointpos name='joint4' joint='wrist_1_joint'/>
        <jointpos name='joint5' joint='wrist_2_joint'/>
        <jointpos name='joint6' joint='wrist_3_joint'/>

        <jointvel name='joint1_vel' joint='shoulder_pan_joint'/>
        <jointvel name='joint2_vel' joint='shoulder_lift_joint'/>
        <jointvel name='joint3_vel' joint='elbow_joint'/>
        <jointvel name='joint4_vel' joint='wrist_1_joint'/>
        <jointvel name='joint5_vel' joint='wrist_2_joint'/>
        <jointvel name='joint6_vel' joint='wrist_3_joint'/>
    </sensor>
</mujoco>