<mujoco model="ur5">
    <compiler angle="radian" meshdir="collision" />
    <!-- <size njmax="500" nconmax="100" /> -->
    <worldbody>
        <geom type="box" size="0.5 0.5 0.03" pos="0 0 0.47"/>
        <body name="base_link" pos="0 0 0.5">
            <body name="shoulder_link" pos="0 0 0.089159">
                <inertial pos="0 0 0" mass="3.7" diaginertia="0.0102675 0.0102675 0.00666" />
                <joint name="shoulder_pan_joint" pos="0 0 0" axis="0 0 1" limited="true" range="-3.14159 3.14159" />
                <body name="upper_arm_link" pos="0 0.13585 0" quat="0.707107 0 0.707107 0">
                    <inertial pos="0 0 0.28" mass="8.393" diaginertia="0.226891 0.226891 0.0151074" />
                    <joint name="shoulder_lift_joint" pos="0 0 0" axis="0 1 0" limited="true" range="-3.14159 3.14159" />
                    <body name="forearm_link" pos="0 -0.1197 0.425">
                        <inertial pos="0 0 0.196125" mass="2.275" diaginertia="0.0312168 0.0312168 0.004095" />
                        <joint name="elbow_joint" pos="0 0 0" axis="0 1 0" limited="true" range="-3.14159 3.14159" />
                        <body name="wrist_1_link" pos="0 0 0.39225" quat="0.707107 0 0.707107 0">
                            <inertial pos="0 0.093 0" mass="1.219" diaginertia="0.0025599 0.0025599 0.0021942" />
                            <joint name="wrist_1_joint" pos="0 0 0" axis="0 1 0" limited="true" range="-3.14159 3.14159" />
                            <body name="wrist_2_link" pos="0 0.093 0">
                                <inertial pos="0 0 0.09465" mass="1.219" diaginertia="0.0025599 0.0025599 0.0021942" />
                                <joint name="wrist_2_joint" pos="0 0 0" axis="0 0 1" limited="true" range="-3.14159 3.14159" />
                                <body name="wrist_3_link" pos="0 0 0.09465">
                                    <inertial pos="0 0.06505 0" quat="1.73123e-12 0.707107 -0.707107 1.73123e-12" 
                                            mass="0.1879" diaginertia="0.000132117 8.46959e-05 8.46959e-05" />
                                    <joint name="wrist_3_joint" pos="0 0 0" axis="0 1 0" limited="true" range="-3.14159 3.14159" />
                                </body>
                            </body>
                        </body>
                    </body>
                </body>
            </body>
        </body>
    </worldbody>
</mujoco>