<mujoco model="Cable">
  <compiler angle="radian" autolimits="true"/>
  <size memory="8M"/>
  <statistic meansize="0.0147059" extent="0.407" center="0.2 0 0.5965"/>
  <custom>
    <text name="composite_" data="rope_"/>
  </custom>
  <worldbody>
    <body name="cable0" pos="0 0 0.9">
      <joint type="free"/>
      <body name="B_first">
        <geom name="G0" size="0.003 0.004" pos="0.004 0 0" quat="0.707107 0 -0.707107 0" type="capsule" condim="1" rgba="0.8 0.2 0.1 1"/>
        <site name="S_first" pos="0 0 0" group="3"/>
        <body name="B_1" pos="0.008 0 0">
          <joint name="J_1" pos="0 0 0" type="ball" group="3" stiffness="0.03" damping="0.015"/>
          <geom name="G1" size="0.003 0.004" pos="0.004 0 0" quat="0.707107 0 -0.707107 0" type="capsule" condim="1" rgba="0.8 0.2 0.1 1"/>
          <body name="B_2" pos="0.008 0 0">
            <joint name="J_2" pos="0 0 0" type="ball" group="3" stiffness="0.03" damping="0.015"/>
            <geom name="G2" size="0.003 0.004" pos="0.004 0 0" quat="0.707107 0 -0.707107 0" type="capsule" condim="1" rgba="0.8 0.2 0.1 1"/>
            <body name="B_3" pos="0.008 0 0">
              <joint name="J_3" pos="0 0 0" type="ball" group="3" stiffness="0.03" damping="0.015"/>
              <geom name="G3" size="0.003 0.004" pos="0.004 0 0" quat="0.707107 0 -0.707107 0" type="capsule" condim="1" rgba="0.8 0.2 0.1 1"/>
              <body name="B_4" pos="0.008 0 0">
                <joint name="J_4" pos="0 0 0" type="ball" group="3" stiffness="0.03" damping="0.015"/>
                <geom name="G4" size="0.003 0.004" pos="0.004 0 0" quat="0.707107 0 -0.707107 0" type="capsule" condim="1" rgba="0.8 0.2 0.1 1"/>
                <body name="B_5" pos="0.008 0 0">
                  <joint name="J_5" pos="0 0 0" type="ball" group="3" stiffness="0.03" damping="0.015"/>
                  <geom name="G5" size="0.003 0.004" pos="0.004 0 0" quat="0.707107 0 -0.707107 0" type="capsule" condim="1" rgba="0.8 0.2 0.1 1"/>
                  <body name="B_6" pos="0.008 0 0">
                    <joint name="J_6" pos="0 0 0" type="ball" group="3" stiffness="0.03" damping="0.015"/>
                    <geom name="G6" size="0.003 0.004" pos="0.004 0 0" quat="0.707107 0 -0.707107 0" type="capsule" condim="1" rgba="0.8 0.2 0.1 1"/>
                    <body name="B_7" pos="0.008 0 0">
                      <joint name="J_7" pos="0 0 0" type="ball" group="3" stiffness="0.03" damping="0.015"/>
                      <geom name="G7" size="0.003 0.004" pos="0.004 0 0" quat="0.707107 0 -0.707107 0" type="capsule" condim="1" rgba="0.8 0.2 0.1 1"/>
                      <body name="B_8" pos="0.00799999 0 0">
                        <joint name="J_8" pos="0 0 0" type="ball" group="3" stiffness="0.03" damping="0.015"/>
                        <geom name="G8" size="0.003 0.004" pos="0.004 0 0" quat="0.707107 0 -0.707107 0" type="capsule" condim="1" rgba="0.8 0.2 0.1 1"/>
                        <body name="B_9" pos="0.008 0 0">
                          <joint name="J_9" pos="0 0 0" type="ball" group="3" stiffness="0.03" damping="0.015"/>
                          <geom name="G9" size="0.003 0.004" pos="0.004 0 0" quat="0.707107 0 -0.707107 0" type="capsule" condim="1" rgba="0.8 0.2 0.1 1"/>
                          <body name="B_10" pos="0.008 0 0">
                            <joint name="J_10" pos="0 0 0" type="ball" group="3" stiffness="0.03" damping="0.015"/>
                            <geom name="G10" size="0.003 0.004" pos="0.004 0 0" quat="0.707107 0 -0.707107 0" type="capsule" condim="1" rgba="0.8 0.2 0.1 1"/>
                            <body name="B_11" pos="0.008 0 0">
                              <joint name="J_11" pos="0 0 0" type="ball" group="3" stiffness="0.03" damping="0.015"/>
                              <geom name="G11" size="0.003 0.004" pos="0.004 0 0" quat="0.707107 0 -0.707107 0" type="capsule" condim="1" rgba="0.8 0.2 0.1 1"/>
                              <body name="B_12" pos="0.008 0 0">
                                <joint name="J_12" pos="0 0 0" type="ball" group="3" stiffness="0.03" damping="0.015"/>
                                <geom name="G12" size="0.003 0.004" pos="0.004 0 0" quat="0.707107 0 -0.707107 0" type="capsule" condim="1" rgba="0.8 0.2 0.1 1"/>
                                <body name="B_13" pos="0.008 0 0">
                                  <joint name="J_13" pos="0 0 0" type="ball" group="3" stiffness="0.03" damping="0.015"/>
                                  <geom name="G13" size="0.003 0.004" pos="0.004 0 0" quat="0.707107 0 -0.707107 0" type="capsule" condim="1" rgba="0.8 0.2 0.1 1"/>
                                  <body name="B_14" pos="0.00799999 0 0">
                                    <joint name="J_14" pos="0 0 0" type="ball" group="3" stiffness="0.03" damping="0.015"/>
                                    <geom name="G14" size="0.003 0.004" pos="0.004 0 0" quat="0.707107 0 -0.707107 0" type="capsule" condim="1" rgba="0.8 0.2 0.1 1"/>
                                    <body name="B_15" pos="0.00800001 0 0">
                                      <joint name="J_15" pos="0 0 0" type="ball" group="3" stiffness="0.03" damping="0.015"/>
                                      <geom name="G15" size="0.003 0.004" pos="0.004 0 0" quat="0.707107 0 -0.707107 0" type="capsule" condim="1" rgba="0.8 0.2 0.1 1"/>
                                      <body name="B_16" pos="0.008 0 0">
                                        <joint name="J_16" pos="0 0 0" type="ball" group="3" stiffness="0.03" damping="0.015"/>
                                        <geom name="G16" size="0.003 0.004" pos="0.004 0 0" quat="0.707107 0 -0.707107 0" type="capsule" condim="1" rgba="0.8 0.2 0.1 1"/>
                                        <body name="B_17" pos="0.00799999 0 0">
                                          <joint name="J_17" pos="0 0 0" type="ball" group="3" stiffness="0.03" damping="0.015"/>
                                          <geom name="G17" size="0.003 0.00399999" pos="0.00399999 0 0" quat="0.707107 0 -0.707107 0" type="capsule" condim="1" rgba="0.8 0.2 0.1 1"/>
                                          <body name="B_18" pos="0.008 0 0">
                                            <joint name="J_18" pos="0 0 0" type="ball" group="3" stiffness="0.03" damping="0.015"/>
                                            <geom name="G18" size="0.003 0.004" pos="0.004 0 0" quat="0.707107 0 -0.707107 0" type="capsule" condim="1" rgba="0.8 0.2 0.1 1"/>
                                            <body name="B_19" pos="0.008 0 0">
                                              <joint name="J_19" pos="0 0 0" type="ball" group="3" stiffness="0.03" damping="0.015"/>
                                              <geom name="G19" size="0.003 0.004" pos="0.004 0 0" quat="0.707107 0 -0.707107 0" type="capsule" condim="1" rgba="0.8 0.2 0.1 1"/>
                                              <body name="B_20" pos="0.008 0 0">
                                                <joint name="J_20" pos="0 0 0" type="ball" group="3" stiffness="0.03" damping="0.015"/>
                                                <geom name="G20" size="0.003 0.004" pos="0.004 0 0" quat="0.707107 0 -0.707107 0" type="capsule" condim="1" rgba="0.8 0.2 0.1 1"/>
                                                <body name="B_21" pos="0.008 0 0">
                                                  <joint name="J_21" pos="0 0 0" type="ball" group="3" stiffness="0.03" damping="0.015"/>
                                                  <geom name="G21" size="0.003 0.004" pos="0.004 0 0" quat="0.707107 0 -0.707107 0" type="capsule" condim="1" rgba="0.8 0.2 0.1 1"/>
                                                  <body name="B_22" pos="0.008 0 0">
                                                    <joint name="J_22" pos="0 0 0" type="ball" group="3" stiffness="0.03" damping="0.015"/>
                                                    <geom name="G22" size="0.003 0.004" pos="0.004 0 0" quat="0.707107 0 -0.707107 0" type="capsule" condim="1" rgba="0.8 0.2 0.1 1"/>
                                                    <body name="B_23" pos="0.008 0 0">
                                                      <joint name="J_23" pos="0 0 0" type="ball" group="3" stiffness="0.03" damping="0.015"/>
                                                      <geom name="G23" size="0.003 0.004" pos="0.004 0 0" quat="0.707107 0 -0.707107 0" type="capsule" condim="1" rgba="0.8 0.2 0.1 1"/>
                                                      <body name="B_24" pos="0.008 0 0">
                                                        <joint name="J_24" pos="0 0 0" type="ball" group="3" stiffness="0.03" damping="0.015"/>
                                                        <geom name="G24" size="0.003 0.004" pos="0.004 0 0" quat="0.707107 0 -0.707107 0" type="capsule" condim="1" rgba="0.8 0.2 0.1 1"/>
                                                        <body name="B_25" pos="0.008 0 0">
                                                          <joint name="J_25" pos="0 0 0" type="ball" group="3" stiffness="0.03" damping="0.015"/>
                                                          <geom name="G25" size="0.003 0.004" pos="0.004 0 0" quat="0.707107 0 -0.707107 0" type="capsule" condim="1" rgba="0.8 0.2 0.1 1"/>
                                                          <body name="B_26" pos="0.008 0 0">
                                                            <joint name="J_26" pos="0 0 0" type="ball" group="3" stiffness="0.03" damping="0.015"/>
                                                            <geom name="G26" size="0.003 0.004" pos="0.004 0 0" quat="0.707107 0 -0.707107 0" type="capsule" condim="1" rgba="0.8 0.2 0.1 1"/>
                                                            <body name="B_27" pos="0.008 0 0">
                                                              <joint name="J_27" pos="0 0 0" type="ball" group="3" stiffness="0.03" damping="0.015"/>
                                                              <geom name="G27" size="0.003 0.004" pos="0.004 0 0" quat="0.707107 0 -0.707107 0" type="capsule" condim="1" rgba="0.8 0.2 0.1 1"/>
                                                              <body name="B_28" pos="0.00799999 0 0">
                                                                <joint name="J_28" pos="0 0 0" type="ball" group="3" stiffness="0.03" damping="0.015"/>
                                                                <geom name="G28" size="0.003 0.00399999" pos="0.00399999 0 0" quat="0.707107 0 -0.707107 0" type="capsule" condim="1" rgba="0.8 0.2 0.1 1"/>
                                                                <body name="B_29" pos="0.008 0 0">
                                                                  <joint name="J_29" pos="0 0 0" type="ball" group="3" stiffness="0.03" damping="0.015"/>
                                                                  <geom name="G29" size="0.003 0.004" pos="0.004 0 0" quat="0.707107 0 -0.707107 0" type="capsule" condim="1" rgba="0.8 0.2 0.1 1"/>
                                                                  <body name="B_30" pos="0.008 0 0">
                                                                    <joint name="J_30" pos="0 0 0" type="ball" group="3" stiffness="0.03" damping="0.015"/>
                                                                    <geom name="G30" size="0.003 0.004" pos="0.004 0 0" quat="0.707107 0 -0.707107 0" type="capsule" condim="1" rgba="0.8 0.2 0.1 1"/>
                                                                    <body name="B_31" pos="0.00800002 0 0">
                                                                      <joint name="J_31" pos="0 0 0" type="ball" group="3" stiffness="0.03" damping="0.015"/>
                                                                      <geom name="G31" size="0.003 0.00400001" pos="0.00400001 0 0" quat="0.707107 0 -0.707107 0" type="capsule" condim="1" rgba="0.8 0.2 0.1 1"/>
                                                                      <body name="B_32" pos="0.00799999 0 0">
                                                                        <joint name="J_32" pos="0 0 0" type="ball" group="3" stiffness="0.03" damping="0.015"/>
                                                                        <geom name="G32" size="0.003 0.00399999" pos="0.00399999 0 0" quat="0.707107 0 -0.707107 0" type="capsule" condim="1" rgba="0.8 0.2 0.1 1"/>
                                                                        <body name="B_33" pos="0.00800002 0 0">
                                                                          <joint name="J_33" pos="0 0 0" type="ball" group="3" stiffness="0.03" damping="0.015"/>
                                                                          <geom name="G33" size="0.003 0.00400001" pos="0.00400001 0 0" quat="0.707107 0 -0.707107 0" type="capsule" condim="1" rgba="0.8 0.2 0.1 1"/>
                                                                          <body name="B_34" pos="0.00799999 0 0">
                                                                            <joint name="J_34" pos="0 0 0" type="ball" group="3" stiffness="0.03" damping="0.015"/>
                                                                            <geom name="G34" size="0.003 0.00399999" pos="0.00399999 0 0" quat="0.707107 0 -0.707107 0" type="capsule" condim="1" rgba="0.8 0.2 0.1 1"/>
                                                                            <body name="B_35" pos="0.00799999 0 0">
                                                                              <joint name="J_35" pos="0 0 0" type="ball" group="3" stiffness="0.03" damping="0.015"/>
                                                                              <geom name="G35" size="0.003 0.00399999" pos="0.00399999 0 0" quat="0.707107 0 -0.707107 0" type="capsule" condim="1" rgba="0.8 0.2 0.1 1"/>
                                                                              <body name="B_36" pos="0.00800002 0 0">
                                                                                <joint name="J_36" pos="0 0 0" type="ball" group="3" stiffness="0.03" damping="0.015"/>
                                                                                <geom name="G36" size="0.003 0.00400001" pos="0.00400001 0 0" quat="0.707107 0 -0.707107 0" type="capsule" condim="1" rgba="0.8 0.2 0.1 1"/>
                                                                                <body name="B_37" pos="0.00799999 0 0">
                                                                                  <joint name="J_37" pos="0 0 0" type="ball" group="3" stiffness="0.03" damping="0.015"/>
                                                                                  <geom name="G37" size="0.003 0.00399999" pos="0.00399999 0 0" quat="0.707107 0 -0.707107 0" type="capsule" condim="1" rgba="0.8 0.2 0.1 1"/>
                                                                                  <body name="B_38" pos="0.00800002 0 0">
                                                                                    <joint name="J_38" pos="0 0 0" type="ball" group="3" stiffness="0.03" damping="0.015"/>
                                                                                    <geom name="G38" size="0.003 0.00400001" pos="0.00400001 0 0" quat="0.707107 0 -0.707107 0" type="capsule" condim="1" rgba="0.8 0.2 0.1 1"/>
                                                                                    <body name="B_39" pos="0.00799999 0 0">
                                                                                      <joint name="J_39" pos="0 0 0" type="ball" group="3" stiffness="0.03" damping="0.015"/>
                                                                                      <geom name="G39" size="0.003 0.00399999" pos="0.00399999 0 0" quat="0.707107 0 -0.707107 0" type="capsule" condim="1" rgba="0.8 0.2 0.1 1"/>
                                                                                      <body name="B_40" pos="0.00800002 0 0">
                                                                                        <joint name="J_40" pos="0 0 0" type="ball" group="3" stiffness="0.03" damping="0.015"/>
                                                                                        <geom name="G40" size="0.003 0.00400001" pos="0.00400001 0 0" quat="0.707107 0 -0.707107 0" type="capsule" condim="1" rgba="0.8 0.2 0.1 1"/>
                                                                                        <body name="B_41" pos="0.00799999 0 0">
                                                                                          <joint name="J_41" pos="0 0 0" type="ball" group="3" stiffness="0.03" damping="0.015"/>
                                                                                          <geom name="G41" size="0.003 0.00399999" pos="0.00399999 0 0" quat="0.707107 0 -0.707107 0" type="capsule" condim="1" rgba="0.8 0.2 0.1 1"/>
                                                                                          <body name="B_42" pos="0.00800002 0 0">
                                                                                            <joint name="J_42" pos="0 0 0" type="ball" group="3" stiffness="0.03" damping="0.015"/>
                                                                                            <geom name="G42" size="0.003 0.00400001" pos="0.00400001 0 0" quat="0.707107 0 -0.707107 0" type="capsule" condim="1" rgba="0.8 0.2 0.1 1"/>
                                                                                            <body name="B_43" pos="0.00799999 0 0">
                                                                                              <joint name="J_43" pos="0 0 0" type="ball" group="3" stiffness="0.03" damping="0.015"/>
                                                                                              <geom name="G43" size="0.003 0.00399999" pos="0.00399999 0 0" quat="0.707107 0 -0.707107 0" type="capsule" condim="1" rgba="0.8 0.2 0.1 1"/>
                                                                                              <body name="B_44" pos="0.00800002 0 0">
                                                                                                <joint name="J_44" pos="0 0 0" type="ball" group="3" stiffness="0.03" damping="0.015"/>
                                                                                                <geom name="G44" size="0.003 0.00400001" pos="0.00400001 0 0" quat="0.707107 0 -0.707107 0" type="capsule" condim="1" rgba="0.8 0.2 0.1 1"/>
                                                                                                <body name="B_45" pos="0.00799999 0 0">
                                                                                                  <joint name="J_45" pos="0 0 0" type="ball" group="3" stiffness="0.03" damping="0.015"/>
                                                                                                  <geom name="G45" size="0.003 0.00399999" pos="0.00399999 0 0" quat="0.707107 0 -0.707107 0" type="capsule" condim="1" rgba="0.8 0.2 0.1 1"/>
                                                                                                  <body name="B_46" pos="0.00799999 0 0">
                                                                                                    <joint name="J_46" pos="0 0 0" type="ball" group="3" stiffness="0.03" damping="0.015"/>
                                                                                                    <geom name="G46" size="0.003 0.00399999" pos="0.00399999 0 0" quat="0.707107 0 -0.707107 0" type="capsule" condim="1" rgba="0.8 0.2 0.1 1"/>
                                                                                                    <body name="B_47" pos="0.00800002 0 0">
                                                                                                      <joint name="J_47" pos="0 0 0" type="ball" group="3" stiffness="0.03" damping="0.015"/>
                                                                                                      <geom name="G47" size="0.003 0.00400001" pos="0.00400001 0 0" quat="0.707107 0 -0.707107 0" type="capsule" condim="1" rgba="0.8 0.2 0.1 1"/>
                                                                                                      <body name="B_48" pos="0.00799999 0 0">
                                                                                                        <joint name="J_48" pos="0 0 0" type="ball" group="3" stiffness="0.03" damping="0.015"/>
                                                                                                        <geom name="G48" size="0.003 0.00399999" pos="0.00399999 0 0" quat="0.707107 0 -0.707107 0" type="capsule" condim="1" rgba="0.8 0.2 0.1 1"/>
                                                                                                        <body name="B_last" pos="0.00800002 0 0">
                                                                                                          <joint name="J_last" pos="0 0 0" type="ball" group="3" stiffness="0.03" damping="0.015"/>
                                                                                                          <geom name="G49" size="0.003 0.00400001" pos="0.00400001 0 0" quat="0.707107 0 -0.707107 0" type="capsule" condim="1" rgba="0.8 0.2 0.1 1"/>
                                                                                                          <site name="S_last" pos="0.00800002 0 0" group="3"/>
                                                                                                        </body>
                                                                                                      </body>
                                                                                                    </body>
                                                                                                  </body>
                                                                                                </body>
                                                                                              </body>
                                                                                            </body>
                                                                                          </body>
                                                                                        </body>
                                                                                      </body>
                                                                                    </body>
                                                                                  </body>
                                                                                </body>
                                                                              </body>
                                                                            </body>
                                                                          </body>
                                                                        </body>
                                                                      </body>
                                                                    </body>
                                                                  </body>
                                                                </body>
                                                              </body>
                                                            </body>
                                                          </body>
                                                        </body>
                                                      </body>
                                                    </body>
                                                  </body>
                                                </body>
                                              </body>
                                            </body>
                                          </body>
                                        </body>
                                      </body>
                                    </body>
                                  </body>
                                </body>
                              </body>
                            </body>
                          </body>
                        </body>
                      </body>
                    </body>
                  </body>
                </body>
              </body>
            </body>
          </body>
        </body>
      </body>
    </body>
  </worldbody>
  <contact>
    <exclude body1="B_first" body2="B_1"/>
    <exclude body1="B_1" body2="B_2"/>
    <exclude body1="B_2" body2="B_3"/>
    <exclude body1="B_3" body2="B_4"/>
    <exclude body1="B_4" body2="B_5"/>
    <exclude body1="B_5" body2="B_6"/>
    <exclude body1="B_6" body2="B_7"/>
    <exclude body1="B_7" body2="B_8"/>
    <exclude body1="B_8" body2="B_9"/>
    <exclude body1="B_9" body2="B_10"/>
    <exclude body1="B_10" body2="B_11"/>
    <exclude body1="B_11" body2="B_12"/>
    <exclude body1="B_12" body2="B_13"/>
    <exclude body1="B_13" body2="B_14"/>
    <exclude body1="B_14" body2="B_15"/>
    <exclude body1="B_15" body2="B_16"/>
    <exclude body1="B_16" body2="B_17"/>
    <exclude body1="B_17" body2="B_18"/>
    <exclude body1="B_18" body2="B_19"/>
    <exclude body1="B_19" body2="B_20"/>
    <exclude body1="B_20" body2="B_21"/>
    <exclude body1="B_21" body2="B_22"/>
    <exclude body1="B_22" body2="B_23"/>
    <exclude body1="B_23" body2="B_24"/>
    <exclude body1="B_24" body2="B_25"/>
    <exclude body1="B_25" body2="B_26"/>
    <exclude body1="B_26" body2="B_27"/>
    <exclude body1="B_27" body2="B_28"/>
    <exclude body1="B_28" body2="B_29"/>
    <exclude body1="B_29" body2="B_30"/>
    <exclude body1="B_30" body2="B_31"/>
    <exclude body1="B_31" body2="B_32"/>
    <exclude body1="B_32" body2="B_33"/>
    <exclude body1="B_33" body2="B_34"/>
    <exclude body1="B_34" body2="B_35"/>
    <exclude body1="B_35" body2="B_36"/>
    <exclude body1="B_36" body2="B_37"/>
    <exclude body1="B_37" body2="B_38"/>
    <exclude body1="B_38" body2="B_39"/>
    <exclude body1="B_39" body2="B_40"/>
    <exclude body1="B_40" body2="B_41"/>
    <exclude body1="B_41" body2="B_42"/>
    <exclude body1="B_42" body2="B_43"/>
    <exclude body1="B_43" body2="B_44"/>
    <exclude body1="B_44" body2="B_45"/>
    <exclude body1="B_45" body2="B_46"/>
    <exclude body1="B_46" body2="B_47"/>
    <exclude body1="B_47" body2="B_48"/>
    <exclude body1="B_48" body2="B_last"/>
  </contact>
</mujoco>